Workbook

Sheet 学习总览
A1: 数据结构 × 算法模式 | 我的 LeetCode 学习地图
A3: 建议先每个专题完成 5～8 道核心题，再补齐专题练习；独立思考、复盘、间隔重做，比追求刷题总量更重要。
A5: 第一阶段 · Easy
A7: 顺序 | B7: 专题 | C7: 收录题数 | D7: 已完成 | E7: 进行中 | F7: 完成率 | G7: 本专题要建立的能力 | H7: 建议节奏
A8: 1 | B8: 01 数组与基础模拟 | C8: =COUNTIF(Easy题单!$B$5:$B$226,B8) -> 22 | D8: =COUNTIFS(Easy题单!$B$5:$B$226,B8,Easy题单!$G$5:$G$226,"已完成") -> 3 | E8: =COUNTIFS(Easy题单!$B$5:$B$226,B8,Easy题单!$G$5:$G$226,"进行中") -> 0 | F8: =IFERROR(D8/C8,0) -> 0.13636364 | G8: 索引、遍历、原地修改、模拟 | H8: 建议先选 8 道
A9: 2 | B9: 02 字符串操作 | C9: =COUNTIF(Easy题单!$B$5:$B$226,B9) -> 22 | D9: =COUNTIFS(Easy题单!$B$5:$B$226,B9,Easy题单!$G$5:$G$226,"已完成") -> 0 | E9: =COUNTIFS(Easy题单!$B$5:$B$226,B9,Easy题单!$G$5:$G$226,"进行中") -> 0 | F9: =IFERROR(D9/C9,0) -> 0 | G9: 切片、字符处理、比较和解析 | H9: 建议先选 7 道
A10: 3 | B10: 03 哈希表与集合 | C10: =COUNTIF(Easy题单!$B$5:$B$226,B10) -> 22 | D10: =COUNTIFS(Easy题单!$B$5:$B$226,B10,Easy题单!$G$5:$G$226,"已完成") -> 0 | E10: =COUNTIFS(Easy题单!$B$5:$B$226,B10,Easy题单!$G$5:$G$226,"进行中") -> 0 | F10: =IFERROR(D10/C10,0) -> 0 | G10: 集合查重、频次、键值映射 | H10: 建议先选 8 道
A11: 4 | B11: 04 双指针与排序 | C11: =COUNTIF(Easy题单!$B$5:$B$226,B11) -> 22 | D11: =COUNTIFS(Easy题单!$B$5:$B$226,B11,Easy题单!$G$5:$G$226,"已完成") -> 0 | E11: =COUNTIFS(Easy题单!$B$5:$B$226,B11,Easy题单!$G$5:$G$226,"进行中") -> 0 | F11: =IFERROR(D11/C11,0) -> 0 | G11: 快慢指针、排序后处理 | H11: 建议先选 8 道
A12: 5 | B12: 05 二分查找 | C12: =COUNTIF(Easy题单!$B$5:$B$226,B12) -> 12 | D12: =COUNTIFS(Easy题单!$B$5:$B$226,B12,Easy题单!$G$5:$G$226,"已完成") -> 0 | E12: =COUNTIFS(Easy题单!$B$5:$B$226,B12,Easy题单!$G$5:$G$226,"进行中") -> 0 | F12: =IFERROR(D12/C12,0) -> 0 | G12: 闭区间/半开区间与单调性 | H12: 12 道即可，重视边界
A13: 6 | B13: 06 单向链表 | C13: =COUNTIF(Easy题单!$B$5:$B$226,B13) -> 10 | D13: =COUNTIFS(Easy题单!$B$5:$B$226,B13,Easy题单!$G$5:$G$226,"已完成") -> 0 | E13: =COUNTIFS(Easy题单!$B$5:$B$226,B13,Easy题单!$G$5:$G$226,"进行中") -> 0 | F13: =IFERROR(D13/C13,0) -> 0 | G13: 节点引用、dummy、快慢指针 | H13: 10 道经典，建议全做
A14: 7 | B14: 07 栈与队列 | C14: =COUNTIF(Easy题单!$B$5:$B$226,B14) -> 15 | D14: =COUNTIFS(Easy题单!$B$5:$B$226,B14,Easy题单!$G$5:$G$226,"已完成") -> 0 | E14: =COUNTIFS(Easy题单!$B$5:$B$226,B14,Easy题单!$G$5:$G$226,"进行中") -> 0 | F14: =IFERROR(D14/C14,0) -> 0 | G14: LIFO/FIFO、单调栈、结构设计 | H14: 先做 8 道
A15: 8 | B15: 08 二叉树与 BST | C15: =COUNTIF(Easy题单!$B$5:$B$226,B15) -> 26 | D15: =COUNTIFS(Easy题单!$B$5:$B$226,B15,Easy题单!$G$5:$G$226,"已完成") -> 0 | E15: =COUNTIFS(Easy题单!$B$5:$B$226,B15,Easy题单!$G$5:$G$226,"进行中") -> 0 | F15: =IFERROR(D15/C15,0) -> 0 | G15: DFS/BFS、递归、BST 性质 | H15: 先做遍历和深度题
A16: 9 | B16: 09 矩阵与图的初步 | C16: =COUNTIF(Easy题单!$B$5:$B$226,B16) -> 20 | D16: =COUNTIFS(Easy题单!$B$5:$B$226,B16,Easy题单!$G$5:$G$226,"已完成") -> 0 | E16: =COUNTIFS(Easy题单!$B$5:$B$226,B16,Easy题单!$G$5:$G$226,"进行中") -> 0 | F16: =IFERROR(D16/C16,0) -> 0 | G16: 二维索引、网格遍历、图连通 | H16: 图题作为后半段
A17: 10 | B17: 10 前缀和·贪心·DP | C17: =COUNTIF(Easy题单!$B$5:$B$226,B17) -> 21 | D17: =COUNTIFS(Easy题单!$B$5:$B$226,B17,Easy题单!$G$5:$G$226,"已完成") -> 0 | E17: =COUNTIFS(Easy题单!$B$5:$B$226,B17,Easy题单!$G$5:$G$226,"进行中") -> 0 | F17: =IFERROR(D17/C17,0) -> 0 | G17: 前缀、固定窗口、贪心、DP | H17: 优先理解状态变化
A18: 11 | B18: 11 数学与位运算 | C18: =COUNTIF(Easy题单!$B$5:$B$226,B18) -> 22 | D18: =COUNTIFS(Easy题单!$B$5:$B$226,B18,Easy题单!$G$5:$G$226,"已完成") -> 0 | E18: =COUNTIFS(Easy题单!$B$5:$B$226,B18,Easy题单!$G$5:$G$226,"进行中") -> 0 | F18: =IFERROR(D18/C18,0) -> 0 | G18: 数值模拟、二进制、异或 | H18: 重点在位运算性质
A19: 12 | B19: 12 高级结构起步 | C19: =COUNTIF(Easy题单!$B$5:$B$226,B19) -> 8 | D19: =COUNTIFS(Easy题单!$B$5:$B$226,B19,Easy题单!$G$5:$G$226,"已完成") -> 0 | E19: =COUNTIFS(Easy题单!$B$5:$B$226,B19,Easy题单!$G$5:$G$226,"进行中") -> 0 | F19: =IFERROR(D19/C19,0) -> 0 | G19: 堆、优先队列、设计类 | H19: 体验即可，随后转 Medium
B20: Easy 总计 | C20: =SUM(C8:C19) -> 222 | D20: =SUM(D8:D19) -> 3 | E20: =SUM(E8:E19) -> 0 | F20: =IFERROR(D20/C20,0) -> 0.013513514
A23: 第二阶段 · Medium 过渡（28 道，不计入上方完成率）
A24: 三组依次进行：数组/字符串/哈希 → 链表/栈/树 → 图/高级结构/动态规划。详见「Medium进阶」。

Sheet Easy题单
A1: LeetCode · Easy 系统化学习题单 | 按数据结构与算法技巧排序
A3: 按表格顺序学习；完成一题后修改「学习状态」，记录自己的思路与复杂度。每题独立归入一个主专题，不重复计数。
A4: 阶段 | B4: 专题 | C4: 题号 | D4: 中文题名 | E4: 核心训练点 | F4: 难度 | G4: 学习状态 | H4: 已接触 | I4: 力扣题目链接 | J4: 复盘笔记
A5: Easy | B5: 01 数组与基础模拟 | C5: 1920 | D5: 基于排列构建数组 | E5: 索引映射 | F5: 简单 | G5: 已完成 | I5: https://leetcode.cn/problems/build-array-from-permutation/
A6: Easy | B6: 01 数组与基础模拟 | C6: 1929 | D6: 数组串联 | E6: 列表拼接 | F6: 简单 | G6: 已完成 | I6: https://leetcode.cn/problems/concatenation-of-array/
A7: Easy | B7: 01 数组与基础模拟 | C7: 1470 | D7: 重新排列数组 | E7: 交错访问 | F7: 简单 | G7: 已完成 | I7: https://leetcode.cn/problems/shuffle-the-array/
A8: Easy | B8: 01 数组与基础模拟 | C8: 1295 | D8: 统计位数为偶数的数字 | E8: 逐元素判断 | F8: 简单 | G8: 未开始 | I8: https://leetcode.cn/problems/find-numbers-with-even-number-of-digits/
A9: Easy | B9: 01 数组与基础模拟 | C9: 485 | D9: 最大连续 1 的个数 | E9: 连续计数 | F9: 简单 | G9: 未开始 | I9: https://leetcode.cn/problems/max-consecutive-ones/
A10: Easy | B10: 01 数组与基础模拟 | C10: 66 | D10: 加一 | E10: 进位处理 | F10: 简单 | G10: 未开始 | I10: https://leetcode.cn/problems/plus-one/
A11: Easy | B11: 01 数组与基础模拟 | C11: 1365 | D11: 有多少小于当前数字的数字 | E11: 计数与枚举 | F11: 简单 | G11: 未开始 | I11: https://leetcode.cn/problems/how-many-numbers-are-smaller-than-the-current-number/
A12: Easy | B12: 01 数组与基础模拟 | C12: 1431 | D12: 拥有最多糖果的孩子 | E12: 遍历与最大值 | F12: 简单 | G12: 未开始 | I12: https://leetcode.cn/problems/kids-with-the-greatest-number-of-candies/
A13: Easy | B13: 01 数组与基础模拟 | C13: 1512 | D13: 好数对的数目 | E13: 两层循环与计数 | F13: 简单 | G13: 未开始 | I13: https://leetcode.cn/problems/number-of-good-pairs/
A14: Easy | B14: 01 数组与基础模拟 | C14: 1748 | D14: 唯一元素的和 | E14: 频率统计 | F14: 简单 | G14: 未开始 | I14: https://leetcode.cn/problems/sum-of-unique-elements/
A15: Easy | B15: 01 数组与基础模拟 | C15: 1389 | D15: 按既定顺序创建目标数组 | E15: 列表插入 | F15: 简单 | G15: 未开始 | I15: https://leetcode.cn/problems/create-target-array-in-the-given-order/
A16: Easy | B16: 01 数组与基础模拟 | C16: 1313 | D16: 解压缩编码列表 | E16: 扩展序列 | F16: 简单 | G16: 未开始 | I16: https://leetcode.cn/problems/decompress-run-length-encoded-list/
... A26: Easy | B26: 01 数组与基础模拟 | C26: 2190 | D26: 数组中紧跟 key 之后出现最频繁的数字 | E26: 相邻频次 | F26: 简单 | G26: 未开始 | I26: https://leetcode.cn/problems/most-frequent-number-following-key-in-an-array/
A27: Easy | B27: 02 字符串操作 | C27: 14 | D27: 最长公共前缀 | E27: 前缀逐步收缩 | F27: 简单 | G27: 未开始 | H27: 曾讨论 | I27: https://leetcode.cn/problems/longest-common-prefix/
A28: Easy | B28: 02 字符串操作 | C28: 58 | D28: 最后一个单词的长度 | E28: 字符串扫描 | F28: 简单 | G28: 未开始 | I28: https://leetcode.cn/problems/length-of-last-word/
A29: Easy | B29: 02 字符串操作 | C29: 125 | D29: 验证回文串 | E29: 过滤与回文 | F29: 简单 | G29: 未开始 | I29: https://leetcode.cn/problems/valid-palindrome/
A30: Easy | B30: 02 字符串操作 | C30: 344 | D30: 反转字符串 | E30: 原地交换 | F30: 简单 | G30: 未开始 | I30: https://leetcode.cn/problems/reverse-string/
A31: Easy | B31: 02 字符串操作 | C31: 345 | D31: 反转字符串中的元音字母 | E31: 条件交换 | F31: 简单 | G31: 未开始 | I31: https://leetcode.cn/problems/reverse-vowels-of-a-string/
A32: Easy | B32: 02 字符串操作 | C32: 434 | D32: 字符串中的单词数 | E32: 空白处理 | F32: 简单 | G32: 未开始 | I32: https://leetcode.cn/problems/number-of-segments-in-a-string/
A33: Easy | B33: 02 字符串操作 | C33: 459 | D33: 重复的子字符串 | E33: 周期检测 | F33: 简单 | G33: 未开始 | I33: https://leetcode.cn/problems/repeated-substring-pattern/
A34: Easy | B34: 02 字符串操作 | C34: 520 | D34: 检测大写字母 | E34: 大小写规则 | F34: 简单 | G34: 未开始 | I34: https://leetcode.cn/problems/detect-capital/
A35: Easy | B35: 02 字符串操作 | C35: 541 | D35: 反转字符串 II | E35: 分块处理 | F35: 简单 | G35: 未开始 | I35: https://leetcode.cn/problems/reverse-string-ii/
A36: Easy | B36: 02 字符串操作 | C36: 557 | D36: 反转字符串中的单词 III | E36: 分词与反转 | F36: 简单 | G36: 未开始 | I36: https://leetcode.cn/problems/reverse-words-in-a-string-iii/
A37: Easy | B37: 02 字符串操作 | C37: 657 | D37: 机器人能否返回原点 | E37: 指令字符统计 | F37: 简单 | G37: 未开始 | I37: https://leetcode.cn/problems/robot-return-to-origin/
A38: Easy | B38: 02 字符串操作 | C38: 709 | D38: 转换成小写字母 | E38: 字符转换 | F38: 简单 | G38: 未开始 | I38: https://leetcode.cn/problems/to-lower-case/
A39: Easy | B39: 02 字符串操作 | C39: 796 | D39: 旋转字符串 | E39: 旋转与拼接 | F39: 简单 | G39: 未开始 | I39: https://leetcode.cn/problems/rotate-string/
... A104: Easy | B104: 05 二分查找 | C104: 2529 | D104: 正整数和负整数的最大计数 | E104: 边界统计 | F104: 简单 | G104: 未开始 | I104: https://leetcode.cn/problems/maximum-count-of-positive-integer-and-negative-integer/
A105: Easy | B105: 06 单向链表 | C105: 21 | D105: 合并两个有序链表 | E105: dummy 与双指针 | F105: 简单 | G105: 未开始 | H105: 曾讨论 | I105: https://leetcode.cn/problems/merge-two-sorted-lists/
A106: Easy | B106: 06 单向链表 | C106: 83 | D106: 删除排序链表中的重复元素 | E106: 原地删节点 | F106: 简单 | G106: 未开始 | I106: https://leetcode.cn/problems/remove-duplicates-from-sorted-list/
A107: Easy | B107: 06 单向链表 | C107: 141 | D107: 环形链表 | E107: 快慢指针 | F107: 简单 | G107: 未开始 | I107: https://leetcode.cn/problems/linked-list-cycle/
A108: Easy | B108: 06 单向链表 | C108: 160 | D108: 相交链表 | E108: 双指针换头 | F108: 简单 | G108: 未开始 | I108: https://leetcode.cn/problems/intersection-of-two-linked-lists/
A109: Easy | B109: 06 单向链表 | C109: 203 | D109: 移除链表元素 | E109: 虚拟头节点 | F109: 简单 | G109: 未开始 | I109: https://leetcode.cn/problems/remove-linked-list-elements/
A110: Easy | B110: 06 单向链表 | C110: 206 | D110: 反转链表 | E110: prev/curr/next | F110: 简单 | G110: 未开始 | I110: https://leetcode.cn/problems/reverse-linked-list/
A111: Easy | B111: 06 单向链表 | C111: 234 | D111: 回文链表 | E111: 找中点与反转 | F111: 简单 | G111: 未开始 | I111: https://leetcode.cn/problems/palindrome-linked-list/
A112: Easy | B112: 06 单向链表 | C112: 237 | D112: 删除链表中的节点 | E112: 不提供头节点 | F112: 简单 | G112: 未开始 | I112: https://leetcode.cn/problems/delete-node-in-a-linked-list/
A113: Easy | B113: 06 单向链表 | C113: 876 | D113: 链表的中间结点 | E113: 快慢指针找中点 | F113: 简单 | G113: 未开始 | I113: https://leetcode.cn/problems/middle-of-the-linked-list/
A114: Easy | B114: 06 单向链表 | C114: 1290 | D114: 二进制链表转整数 | E114: 遍历累积 | F114: 简单 | G114: 未开始 | I114: https://leetcode.cn/problems/convert-binary-number-in-a-linked-list-to-integer/
...

Sheet Medium进阶
A1: 进阶衔接 · 28 道 Medium 代表题 | 完成对应 Easy 专题后再尝试
A3: 这些题不计入 Easy 进度，只是展示后续学习方向。尤其推荐链表、树和图的 Medium 题用于真正理解指针、递归和遍历。
A4: 进阶分组 | B4: 题号 | C4: 中文题名 | D4: 关键技巧 | E4: 学习理由 | F4: 力扣链接 | G4: 学习状态
A5: 01 数组·字符串·哈希 | B5: 3 | C5: 无重复字符的最长子串 | D5: 滑动窗口 | E5: 建议先学窗口 | F5: https://leetcode.cn/problems/longest-substring-without-repeating-characters/ | G5: 未开始
A6: 01 数组·字符串·哈希 | B6: 11 | C6: 盛最多水的容器 | D6: 对向双指针 | E6: 双指针经典 | F6: https://leetcode.cn/problems/container-with-most-water/ | G6: 未开始
A7: 01 数组·字符串·哈希 | B7: 15 | C7: 三数之和 | D7: 排序与双指针 | E7: 去重问题 | F7: https://leetcode.cn/problems/3sum/ | G7: 未开始
A8: 01 数组·字符串·哈希 | B8: 49 | C8: 字母异位词分组 | D8: 哈希分组 | E8: 设计键 | F8: https://leetcode.cn/problems/group-anagrams/ | G8: 未开始
A9: 01 数组·字符串·哈希 | B9: 56 | C9: 合并区间 | D9: 排序与区间 | E9: 区间操作 | F9: https://leetcode.cn/problems/merge-intervals/ | G9: 未开始
A10: 01 数组·字符串·哈希 | B10: 75 | C10: 颜色分类 | D10: 三路划分 | E10: 原地排序 | F10: https://leetcode.cn/problems/sort-colors/ | G10: 未开始
A11: 01 数组·字符串·哈希 | B11: 209 | C11: 长度最小的子数组 | D11: 可变窗口 | E11: 收缩条件 | F11: https://leetcode.cn/problems/minimum-size-subarray-sum/ | G11: 未开始
A12: 01 数组·字符串·哈希 | B12: 238 | C12: 除了自身以外数组的乘积 | D12: 前后缀积 | E12: 无除法 | F12: https://leetcode.cn/problems/product-of-array-except-self/ | G12: 未开始
A13: 02 链表·栈·树 | B13: 2 | C13: 两数相加 | D13: 链表模拟进位 | E13: 节点构建 | F13: https://leetcode.cn/problems/add-two-numbers/ | G13: 未开始
A14: 02 链表·栈·树 | B14: 19 | C14: 删除链表的倒数第 N 个结点 | D14: 快慢指针 | E14: 间距设计 | F14: https://leetcode.cn/problems/remove-nth-node-from-end-of-list/ | G14: 未开始
A15: 02 链表·栈·树 | B15: 24 | C15: 两两交换链表中的节点 | D15: 指针重连 | E15: dummy 进阶 | F15: https://leetcode.cn/problems/swap-nodes-in-pairs/ | G15: 未开始
A16: 02 链表·栈·树 | B16: 92 | C16: 反转链表 II | D16: 局部反转 | E16: 边界处理 | F16: https://leetcode.cn/problems/reverse-linked-list-ii/ | G16: 未开始
... A32: 03 图·高级结构·DP | B32: 78 | C32: 子集 | D32: 回溯 | E32: 状态树 | F32: https://leetcode.cn/problems/subsets/ | G32: 未开始

Sheet 使用说明
A1: 学习说明 | 刷题不仅是做对，还要理解为什么
A4: 如何使用这份题单
A5: ① 先学方法，再做题 | B5: 一个专题先理解关键操作，再连续做 5～8 道题，剩余作为巩固；暂时不要为刷完 222 道而牺牲理解。
A6: ② 一题做三遍 | B6: 第一次独立尝试；第二次用自己的话复盘思路；第三次间隔 3～7 天不看题解重做。
A7: ③ 建议时间分配 | B7: Easy 先独立想约 15～25 分钟；完全没有进展时先看提示，不直接照抄整份答案。根据题目难度灵活调整。
A8: ④ 复杂度复盘 | B8: 每题记录主要数据结构、为何选择它、时间复杂度、额外空间复杂度、最容易错的边界。
A9: ⑤ 可视化辅助 | B9: 复杂的链表指针、栈、树递归、DFS/BFS 及状态转移题用图或可交互演示；简单题优先少量文字与代码。
A10: ⑥ 多标签题目的归类 | B10: 为了学习顺序，每题只归入一个主专题；例如哈希+数组、双指针+字符串属于交叉知识，不代表题目只有一个标签。
A11: ⑦ 已讨论过的题 | B11: 9 回文数；13 罗马数字转整数；14 最长公共前缀；20 有效的括号；21 合并两个有序链表。表格标注“曾讨论”，不代表已熟练掌握。
A12: ⑧ 难度与链接 | B12: 以 2026-10-18 前后力扣公开内容及经典 Easy 分类为依据；平台难度、题名或权限可能调整，以实际题目页面为准。
A13: ⑨ 挑战 Medium 的时机 | B13: 能独立完成该专题约 70% 核心 Easy 题、讲清指针/状态变化及 O 复杂度后，就可以穿插对应 Medium，而不必刷光所有 Easy。
A14: 权威参考资料
A15: 力扣：编程基础 0 到 1 | B15: https://leetcode.cn/studyplan/programming-skills/
A16: 力扣：LeetCode 75 | B16: https://leetcode.cn/studyplan/leetcode-75/
A17: 力扣：数组专题 | B17: https://leetcode.cn/problem-list/array/
A18: 力扣：树专题 | B18: https://leetcode.cn/problem-list/tree/
A19: 力扣：队列专题 | B19: https://leetcode.cn/problem-list/queue/
A20: 力扣：堆 / 优先队列专题 | B20: https://leetcode.cn/problem-list/heap-priority-queue/
